The solution involves wrapping the cleanup function's code within a `try...catch` block to handle potential errors gracefully.

```javascript
import React, { useEffect, useState } from 'react';

const MyComponent = () => {
  const [data, setData] = useState(null);

  useEffect(() => {
    let mounted = true;
    const fetchData = async () => {
      try {
        const response = await fetch('some-url');
        if (mounted) {
          setData(await response.json());
        }
      } catch (error) {
        console.error('Error fetching data:', error);
      } 
      return () => {
        try {
          mounted = false; 
          // Cleanup logic here
        } catch (cleanupError) {
          console.error('Error in cleanup function:', cleanupError);
        }
      };
    };
    fetchData();
  }, []);

  return (
    <View>
      {/* ... */}
    </View>
  );
};
```

By adding the `try...catch` block, any errors thrown during the cleanup phase are caught, logged to the console and prevented from crashing the application.  This provides more robust error handling and makes debugging easier.